Workbook

Sheet Owners Info
A1: Building | B1: Property | C1: Status | D1: GC Status | E1: Unit Type | F1: Unit Owner (WIP) | G1: Email (WIP) | H1: Contact Number | I1: Classification | J1: Effective Date | K1: Expiry Date | L1: Expiry Tracker | M1: Contract (WIP) | N1: AIRBNB | O1: BOOKING .COM | P1: AGODA | Q1: HOSTEEVA | R1: YOUR RENTALS | S1: TRIP.COM | T1: INVENTORY LIST
A2: Avida Storeys 1 | B2: P S1 503 | C2: ACTIVE | D2: FIXED | E2: 2-Bedroom | F2: Nino Donato Pison | G2: n_pison@yahoo.com | I2: Fixed | J2: 45184 | K2: MISSING | L2: =ifs(C2="INACTIVE","INACTIVE",C2="IN PROGRESS","IN PROGRESS",K2="","",K2="MISSING","?",K2-TODAY()>0,K2-TODAY(),K2-TODAY()<0,"EXPIRED") -> ? | N2: P S1 503 | O2: P Fantastic 2BR Option for 8 | P2: P S1 503
A3: Avida Storeys 1 | B3: S S1 717 | C3: ACTIVE | D3: FIXED | E3: 1-Bedroom | F3: Revrose Selyn Pison | G3: n_pison@yahoo.com | I3: Fixed | J3: 45180 | K3: MISSING | L3: =ifs(C3="INACTIVE","INACTIVE",C3="IN PROGRESS","IN PROGRESS",K3="","",K3="MISSING","?",K3-TODAY()>0,K3-TODAY(),K3-TODAY()<0,"EXPIRED") -> ? | N3: S S1 717 | O3: S Urban Dreamscape | P3: S S1 717
A4: Avida Storeys 1 | B4: S1 408 | C4: ACTIVE | D4: FIXED | E4: STOCKROOM | F4: Edgardo Pison | G4: n_pison@yahoo.com | I4: Fixed | J4: 45180 | K4: MISSING | L4: =ifs(C4="INACTIVE","INACTIVE",C4="IN PROGRESS","IN PROGRESS",K4="","",K4="MISSING","?",K4-TODAY()>0,K4-TODAY(),K4-TODAY()<0,"EXPIRED") -> ?
A5: Avida Storeys 1 | B5: S2 S1 210 | C5: ACTIVE | D5: FIXED | E5: 1-Bedroom | F5: Dondon Pison | G5: n_pison@yahoo.com | I5: Fixed | J5: 45458 | K5: 46188 | L5: =ifs(C5="INACTIVE","INACTIVE",C5="IN PROGRESS","IN PROGRESS",K5="","",K5="MISSING","?",K5-TODAY()>0,K5-TODAY(),K5-TODAY()<0,"EXPIRED") -> EXPIRED | N5: S2 S1 210 | O5: S2 Chic Minimalist Escape | P5: S2 S1 210
A6: Avida Storeys 1 | B6: H S1 506 | C6: INACTIVE | D6: N/A | E6: 1-Bedroom | F6: Bacolod Concept Realty Corp. | G6: n_pison@yahoo.com | I6: Fixed | J6: 45061 | K6: MISSING | L6: =ifs(C6="INACTIVE","INACTIVE",C6="IN PROGRESS","IN PROGRESS",K6="","",K6="MISSING","?",K6-TODAY()>0,K6-TODAY(),K6-TODAY()<0,"EXPIRED") -> INACTIVE | N6: H S1 506 | O6: H Incomparable Value
A7: Avida Storeys 1 | B7: Y S1 704 | C7: ACTIVE | D7: NOT YET | E7: 2-Bedroom | F7: Goldamier Ybera Chua | G7: goldameirchua@gycmarketingopc.com | I7: Partnership | J7: 45717 | K7: 46082 | L7: =ifs(C7="INACTIVE","INACTIVE",C7="IN PROGRESS","IN PROGRESS",K7="","",K7="MISSING","?",K7-TODAY()>0,K7-TODAY(),K7-TODAY()<0,"EXPIRED") -> EXPIRED | N7: Y S1 704 | O7: Y Stylish 2BR Option for up to 6 | P7: Y S1 704
A8: Avida Storeys 2 | B8: Y2 S2 203 | C8: ACTIVE | D8: MESSENGER | E8: 1-Bedroom | F8: Ma. Crislyne Mae Espinosa | G8: arlandbarvilla@gmail.com | I8: Partnership | J8: 45506 | K8: 45871 | L8: =ifs(C8="INACTIVE","INACTIVE",C8="IN PROGRESS","IN PROGRESS",K8="","",K8="MISSING","?",K8-TODAY()>0,K8-TODAY(),K8-TODAY()<0,"EXPIRED") -> EXPIRED | M8: Y2 S2 203 - ESPINOSA.pdf | N8: Y2 S2 203 | O8: Y2 Pool & Garden Bliss | P8: Y2 S2 203
A9: Avida Storeys 2 | B9: K2 S2 322 | C9: ACTIVE | D9: FIXED | E9: 1-Bedroom | G9: n_pison@yahoo.com | I9: Fixed | J9: 45245 | K9: MISSING | L9: =ifs(C9="INACTIVE","INACTIVE",C9="IN PROGRESS","IN PROGRESS",K9="","",K9="MISSING","?",K9-TODAY()>0,K9-TODAY(),K9-TODAY()<0,"EXPIRED") -> ? | N9: K2 S2 322 | O9: K2 Nordic Haven | P9: K2 S2 322
A10: Avida Storeys 2 | B10: L S2 716 | C10: ACTIVE | D10: FIXED | E10: 1-Bedroom | F10: Raymund Trenas | G10: raytrenas@gmail.com | I10: Fixed | J10: 45180 | K10: MISSING | L10: =ifs(C10="INACTIVE","INACTIVE",C10="IN PROGRESS","IN PROGRESS",K10="","",K10="MISSING","?",K10-TODAY()>0,K10-TODAY(),K10-TODAY()<0,"EXPIRED") -> ? | N10: L S2 716 | O10: L Iloilo's Quirky Oasis
A11: Avida Storeys 2 | B11: T2 S2 703 | C11: FOR RENEWAL | D11: NOT YET | E11: 1-Bedroom | F11: Leo Paranpan | G11: lparanpan@yahoo.com | H11: (+63) 917 127 3533 | I11: Partnership | J11: 45461 | K11: 45826 | L11: =ifs(C11="INACTIVE","INACTIVE",C11="IN PROGRESS","IN PROGRESS",K11="","",K11="MISSING","?",K11-TODAY()>0,K11-TODAY(),K11-TODAY()<0,"EXPIRED") -> EXPIRED | M11: T2 S2 703 - PARANPAN.pdf | N11: T2 S2 703 | O11: T2 Serene Pool View Escape | P11: T2 S2 703
A12: Avida Tower 1 | B12: D T1 917 | C12: ACTIVE | D12: MESSENGER | E12: Studio | F12: Robert Stanley Po | G12: cltpo@icloud.com | H12: (+63) 917 844 3012 | I12: Partnership | J12: 45809 | K12: 46174 | L12: =ifs(C12="INACTIVE","INACTIVE",C12="IN PROGRESS","IN PROGRESS",K12="","",K12="MISSING","?",K12-TODAY()>0,K12-TODAY(),K12-TODAY()<0,"EXPIRED") -> EXPIRED | N12: D T1 917 | O12: D Peaceful and Comfortable Room | P12: D T1 917
A13: Avida Tower 1 | B13: C3 T1 428 | C13: ACTIVE | D13: MESSENGER | E13: 2-Bedroom | F13: Ramona Beck | G13: mona_beck2001@yahoo.com | H13: (+63) 935 489 5373 | I13: 75/25 Partner | J13: 45635 | K13: 46000 | L13: =ifs(C13="INACTIVE","INACTIVE",C13="IN PROGRESS","IN PROGRESS",K13="","",K13="MISSING","?",K13-TODAY()>0,K13-TODAY(),K13-TODAY()<0,"EXPIRED") -> EXPIRED | N13: C3 T1 428 | O13: C3 Elegant 2BR Condo with Pool View | P13: C3 T1 428
A14: Avida Tower 1 | B14: A3 T1 1524 | C14: INACTIVE | D14: N/A | E14: Studio | F14: Elvie Dofitas | G14: Elvie.dofitas08@gmail.com | H14: (+63) 917 680 0008 | I14: 75/25 Partner | J14: 45600 | K14: 45781 | L14: =ifs(C14="INACTIVE","INACTIVE",C14="IN PROGRESS","IN PROGRESS",K14="","",K14="MISSING","?",K14-TODAY()>0,K14-TODAY(),K14-TODAY()<0,"EXPIRED") -> INACTIVE | M14: A3 T1 1524 - DOFITAS.pdf | N14: A3 T1 1524 | O14: A3 Central Studio Getaway | P14: A3 T1 1524
A15: Avida Tower 1 | B15: V2 T1 306 | C15: ACTIVE | D15: NOT YET | E15: Studio | F15: Dondon Pison | G15: n_pison@yahoo.com | I15: Partnership | L15: =ifs(C15="INACTIVE","INACTIVE",C15="IN PROGRESS","IN PROGRESS",K15="","",K15="MISSING","?",K15-TODAY()>0,K15-TODAY(),K15-TODAY()<0,"EXPIRED") | N15: V2 T1 306 | O15: V2 Relaxing Studio Escape | P15: V2 T1 306
A16: Avida Tower 1 | B16: B AT T1 501 | C16: ACTIVE | D16: VIBER | E16: 1-Bedroom | F16: Angelina Cordero / Sarah Angela Cordero | G16: docangie.thesmileologists@gmail.com | H16: (+63) 905 446 6439 | I16: 85/15 Partner | L16: =ifs(C16="INACTIVE","INACTIVE",C16="IN PROGRESS","IN PROGRESS",K16="","",K16="MISSING","?",K16-TODAY()>0,K16-TODAY(),K16-TODAY()<0,"EXPIRED")
A17: Avida Tower 1 | B17: U2 T1 221 | C17: ACTIVE | D17: VIBER | E17: 1-Bedroom | F17: Ira Villanueva Valenzuela | G17: villanueva_ira@yahoo.com | H17: (+63) 917 305 2499 | I17: Partnership | J17: 45474 | K17: 45839 | L17: =ifs(C17="INACTIVE","INACTIVE",C17="IN PROGRESS","IN PROGRESS",K17="","",K17="MISSING","?",K17-TODAY()>0,K17-TODAY(),K17-TODAY()<0,"EXPIRED") -> EXPIRED | M17: U2 T1 221 - VILLANUEVA.pdf | N17: U2 T1 221 | O17: U2 Spacious 1BR Retreat | P17: U2 T1 221
A18: Avida Tower 2 | B18: T T2 815 | C18: ACTIVE | D18: FIXED | E18: Studio | F18: William Del Rosario | G18: bdelrosario1014@gmail.com | I18: Fixed | L18: =ifs(C18="INACTIVE","INACTIVE",C18="IN PROGRESS","IN PROGRESS",K18="","",K18="MISSING","?",K18-TODAY()>0,K18-TODAY(),K18-TODAY()<0,"EXPIRED") | N18: T T2 815 | O18: T Panoramic Metro View | P18: T T2 815
A19: Avida Tower 2 | B19: E2 T2 309 | C19: ACTIVE | D19: FIXED | E19: Studio | F19: Mary Joyce Torrefranca | G19: cant0910@yahoo.com | H19: (+63) 917 319 5794 | I19: Fixed | J19: 45698 | K19: MISSING | L19: =ifs(C19="INACTIVE","INACTIVE",C19="IN PROGRESS","IN PROGRESS",K19="","",K19="MISSING","?",K19-TODAY()>0,K19-TODAY(),K19-TODAY()<0,"EXPIRED") -> ? | N19: E2 T2 309 | O19: E2 Oasis in the City
A20: Avida Tower 2 | B20: R T2 1423 | C20: ACTIVE | D20: FIXED | E20: Studio | F20: Irene Lachica | G20: irene.lachica@yahoo.com | H20: (+63) 923 741 5922 | I20: Fixed | J20: 45184 | K20: MISSING | L20: =ifs(C20="INACTIVE","INACTIVE",C20="IN PROGRESS","IN PROGRESS",K20="","",K20="MISSING","?",K20-TODAY()>0,K20-TODAY(),K20-TODAY()<0,"EXPIRED") -> ? | N20: R T2 1423 | O20: R Metropolitan Mirage | P20: R T2 1423
A21: Avida Tower 2 | B21: I2 T2 522 | C21: ACTIVE | D21: FIXED | E21: Studio | F21: Lourdes Carney | G21: Lourdes.carney@gmail.com | I21: Fixed | J21: 45294 | K21: MISSING | L21: =ifs(C21="INACTIVE","INACTIVE",C21="IN PROGRESS","IN PROGRESS",K21="","",K21="MISSING","?",K21-TODAY()>0,K21-TODAY(),K21-TODAY()<0,"EXPIRED") -> ? | N21: I2 T2 522 | O21: I2 Sleek City Haven | P21: I2 T2 522
A22: Avida Tower 2 | B22: B2 T2 108 | C22: ACTIVE | D22: FIXED | E22: Studio | F22: Edward Espinosa | G22: mariespinosa3185@gmail.com | I22: Fixed | J22: 45294 | K22: MISSING | L22: =ifs(C22="INACTIVE","INACTIVE",C22="IN PROGRESS","IN PROGRESS",K22="","",K22="MISSING","?",K22-TODAY()>0,K22-TODAY(),K22-TODAY()<0,"EXPIRED") -> ? | N22: B2 T2 108 | O22: B2 Your Go-To Crib
A23: Avida Tower 2 | B23: F T2 1020 | C23: ACTIVE | D23: FIXED | E23: Studio | F23: Kathreen Socorro Piamonte | I23: Fixed | J23: 45022 | K23: MISSING | L23: =ifs(C23="INACTIVE","INACTIVE",C23="IN PROGRESS","IN PROGRESS",K23="","",K23="MISSING","?",K23-TODAY()>0,K23-TODAY(),K23-TODAY()<0,"EXPIRED") -> ? | N23: F T2 1020 | O23: F Best Vlaue in Iloilo | P23: F T2 1020
A24: Avida Tower 2 | B24: N T2 421 | C24: ACTIVE | D24: FIXED | E24: Studio | F24: Roberto Gelvezon | I24: Fixed | J24: 45143 | L24: =ifs(C24="INACTIVE","INACTIVE",C24="IN PROGRESS","IN PROGRESS",K24="","",K24="MISSING","?",K24-TODAY()>0,K24-TODAY(),K24-TODAY()<0,"EXPIRED") | N24: N T2 421 | O24: N Affordable Urban Luxury | P24: N T2 421
A25: Avida Tower 2 | B25: Q T2 420 | C25: ACTIVE | D25: FIXED | E25: Studio | F25: Gerard Teofilo Gelvezon | I25: Fixed | J25: 45184 | K25: MISSING | L25: =ifs(C25="INACTIVE","INACTIVE",C25="IN PROGRESS","IN PROGRESS",K25="","",K25="MISSING","?",K25-TODAY()>0,K25-TODAY(),K25-TODAY()<0,"EXPIRED") -> ? | N25: Q T2 420 | O25: Q Incomparable Comfort for 3 | P25: Q T2 420
A26: Avida Tower 2 | B26: X T2 1021 | C26: ACTIVE | D26: FIXED | E26: Studio | F26: Michael Borro | I26: Fixed | J26: 45107 | K26: 46203 | L26: =ifs(C26="INACTIVE","INACTIVE",C26="IN PROGRESS","IN PROGRESS",K26="","",K26="MISSING","?",K26-TODAY()>0,K26-TODAY(),K26-TODAY()<0,"EXPIRED") -> EXPIRED | N26: X T2 1021 | O26: X Metro Bliss
A27: Avida Tower 2 | B27: H2 T2 521 | C27: ACTIVE | D27: FIXED | E27: Studio | F27: Maria Rita Jardiolin | G27: Ritaj241@yahoo.com | I27: Fixed | J27: 45294 | K27: MISSING | L27: =ifs(C27="INACTIVE","INACTIVE",C27="IN PROGRESS","IN PROGRESS",K27="","",K27="MISSING","?",K27-TODAY()>0,K27-TODAY(),K27-TODAY()<0,"EXPIRED") -> ? | N27: H2 T2 521 | O27: H2 Modern City Condo | P27: H2 T2 521
A28: Avida Tower 2 | B28: Q2 T2 1221 | C28: INACTIVE | D28: N/A | E28: Studio | F28: Maria Grace Puertollano | G28: graceuybico@gmail.com | I28: Partnership | L28: =ifs(C28="INACTIVE","INACTIVE",C28="IN PROGRESS","IN PROGRESS",K28="","",K28="MISSING","?",K28-TODAY()>0,K28-TODAY(),K28-TODAY()<0,"EXPIRED") -> INACTIVE | N28: Q2 T2 1221 | O28: Q2 City View Twin Room | P28: Q2 T2 1221
A29: Avida Tower 2 | B29: A T2 322 | C29: ACTIVE | D29: NOT YET | E29: Studio | F29: Aaron James Sales | G29: Aaronsales.j@gmail.com | I29: 85/15 Partner | J29: 45729 | K29: 45821 | L29: =ifs(C29="INACTIVE","INACTIVE",C29="IN PROGRESS","IN PROGRESS",K29="","",K29="MISSING","?",K29-TODAY()>0,K29-TODAY(),K29-TODAY()<0,"EXPIRED") -> EXPIRED | N29: A T2 322 | O29: A Charming Urban Retreat | P29: A T2 322
A30: Avida Tower 2 | B30: # T2 209 | C30: ACTIVE | D30: VIBER | E30: Studio | F30: Fredilyn Samoro/Katrina Samoro | H30: (+63) 0917 701 0178. 0917 893 6246 | I30: 85/15 Partner | J30: 45769 | K30: 45961 | L30: =ifs(C30="INACTIVE","INACTIVE",C30="IN PROGRESS","IN PROGRESS",K30="","",K30="MISSING","?",K30-TODAY()>0,K30-TODAY(),K30-TODAY()<0,"EXPIRED") -> EXPIRED
A31: Avida Tower 3 | B31: D2 T3 626 | C31: ACTIVE | D31: FIXED | E31: Studio | F31: Donnave Caramat | G31: dgcaramat12@gmail.com | I31: Fixed | J31: 45294 | K31: MISSING | L31: =ifs(C31="INACTIVE","INACTIVE",C31="IN PROGRESS","IN PROGRESS",K31="","",K31="MISSING","?",K31-TODAY()>0,K31-TODAY(),K31-TODAY()<0,"EXPIRED") -> ? | N31: D2 T3 626 | O31: D2 Central Location Condo
A32: Avida Tower 2 | B32: # T2 209
A33: Avida Tower 3 | B33: I T3 725 | C33: INACTIVE | D33: N/A | E33: Studio | F33: Mechelle Balasa Rey | G33: jayson12mendoza15@gmail.com | I33: Fixed | J33: 45070 | K33: MISSING | L33: =ifs(C33="INACTIVE","INACTIVE",C33="IN PROGRESS","IN PROGRESS",K33="","",K33="MISSING","?",K33-TODAY()>0,K33-TODAY(),K33-TODAY()<0,"EXPIRED") -> INACTIVE | N33: I T3 725 | O33: I Best Value Studio
A34: Avida Tower 3 | B34: B3 T3 1011 | C34: ACTIVE | D34: NOT YET | E34: Studio | F34: Gutierrez Dev. Company | G34: gutierrezdevelopment@gmail.com | I34: 75/25 Partner | J34: 45611 | K34: MISSING | L34: =ifs(C34="INACTIVE","INACTIVE",C34="IN PROGRESS","IN PROGRESS",K34="","",K34="MISSING","?",K34-TODAY()>0,K34-TODAY(),K34-TODAY()<0,"EXPIRED") -> ? | N34: B3 T3 1011 | O34: B3 Chic Sunset Studio Escape | P34: B3 T3 1011
A35: Avida Tower 3 | B35: W2 T3 207 | C35: ACTIVE | D35: VIBER | E35: Studio | F35: Pancho Bringas / Christine Magallanes | G35: Ceee_m@yahoo.com | H35: (+63) 917 303 1696 | I35: Partnership | J35: 45506 | K35: 45871 | L35: =ifs(C35="INACTIVE","INACTIVE",C35="IN PROGRESS","IN PROGRESS",K35="","",K35="MISSING","?",K35-TODAY()>0,K35-TODAY(),K35-TODAY()<0,"EXPIRED") -> EXPIRED | N35: W2 T3 207 | O35: W2 Cozy Urban Nest | P35: W2 T3 207
A36: Avida Tower 3 | B36: X2 T3 528 | C36: ACTIVE | D36: VIBER | E36: Studio | F36: Pancho Bringas / Christine Magallanes | G36: Ceee_m@yahoo.com | H36: (+63) 917 303 1696 | I36: Partnership | J36: 45506 | K36: 45871 | L36: =ifs(C36="INACTIVE","INACTIVE",C36="IN PROGRESS","IN PROGRESS",K36="","",K36="MISSING","?",K36-TODAY()>0,K36-TODAY(),K36-TODAY()<0,"EXPIRED") -> EXPIRED | N36: X2 T3 528 | O36: X2 Urban Zen Studio | P36: X2 T3 528
A37: Avida Tower 3 | B37: Z2 T3 526 | C37: ACTIVE | D37: VIBER | E37: Studio | F37: Czarina Ngan | G37: e43eee3esdwafcfvfcffvgvgrdcrxseexttfddfddz;;p-p-p= | H37: (+63) 917 701 8684 | I37: 85/15 Partner | J37: 45769 | K37: 45869 | L37: =ifs(C37="INACTIVE","INACTIVE",C37="IN PROGRESS","IN PROGRESS",K37="","",K37="MISSING","?",K37-TODAY()>0,K37-TODAY(),K37-TODAY()<0,"EXPIRED") -> EXPIRED | N37: Z2 T3 526 | O37: Z2 Modern Zen Hideaway | P37: Z2 T3 526
A38: Avida Tower 3 | B38: M2 T3 424 | C38: ACTIVE | D38: VIBER | E38: Studio | F38: Leyson San Juan | G38: leyson37@gmail.com | H38: (+63) 917 713 7994 | I38: Partnership | J38: 45811 | K38: 46176 | L38: =ifs(C38="INACTIVE","INACTIVE",C38="IN PROGRESS","IN PROGRESS",K38="","",K38="MISSING","?",K38-TODAY()>0,K38-TODAY(),K38-TODAY()<0,"EXPIRED") -> EXPIRED | N38: M2 T3 424 | O38: M2 Minimalist and Cozy Studio | P38: M2 T3 424
A39: Avida Tower 3 | B39: N2 T3 426 | C39: ACTIVE | D39: VIBER | E39: Studio | F39: Leyson San Juan | G39: leyson37@gmail.com | H39: (+63) 917 713 7994 | I39: Partnership | J39: 45811 | K39: 46176 | L39: =ifs(C39="INACTIVE","INACTIVE",C39="IN PROGRESS","IN PROGRESS",K39="","",K39="MISSING","?",K39-TODAY()>0,K39-TODAY(),K39-TODAY()<0,"EXPIRED") -> EXPIRED | N39: N2 T3 426 | O39: N2 Sleek Urban Escape | P39: N2 T3 426
A40: Avida Tower 3 | B40: O2 T3 826 | C40: ACTIVE | D40: VIBER | E40: Studio | F40: Leyson San Juan | G40: leyson37@gmail.com | H40: (+63) 917 713 7994 | I40: Partnership | J40: 45811 | K40: 46176 | L40: =ifs(C40="INACTIVE","INACTIVE",C40="IN PROGRESS","IN PROGRESS",K40="","",K40="MISSING","?",K40-TODAY()>0,K40-TODAY(),K40-TODAY()<0,"EXPIRED") -> EXPIRED | M40: AT T3 826 - SAN JUAN (RENEWAL).pdf | N40: O2 T3 826 | O40: O2 Urban Zen Retreat | P40: O2 T3 826
...

Sheet Expiry Tracker
A1: Building | B1: Property | C1: Unit Owner | D1: Classification | E1: Effective Date | F1: Expiry Date | G1: Expiration Days | H1: Status | I1: Contract | J1: Email | K1: Notes | L1: *Cell Order*
A2: ='Owners Info'!A2 -> Avida Storeys 1 | B2: ='Owners Info'!B2 -> P S1 503 | C2: ='Owners Info'!F2 -> Nino Donato Pison | D2: ='Owners Info'!I2 -> Fixed | E2: ='Owners Info'!J2 -> 45184 | F2: ='Owners Info'!K2 -> MISSING | G2: ='Owners Info'!L2 -> ? | H2: ='Owners Info'!C2 -> ACTIVE | I2: ='Owners Info'!M2 | J2: ='Owners Info'!G2 -> n_pison@yahoo.com | L2: 2
A3: ='Owners Info'!A3 -> Avida Storeys 1 | B3: ='Owners Info'!B3 -> S S1 717 | C3: ='Owners Info'!F3 -> Revrose Selyn Pison | D3: ='Owners Info'!I3 -> Fixed | E3: ='Owners Info'!J3 -> 45180 | F3: ='Owners Info'!K3 -> MISSING | G3: ='Owners Info'!L3 -> ? | H3: ='Owners Info'!C3 -> ACTIVE | I3: ='Owners Info'!M3 | J3: ='Owners Info'!G3 -> n_pison@yahoo.com | L3: 3
A4: ='Owners Info'!A4 -> Avida Storeys 1 | B4: ='Owners Info'!B4 -> S1 408 | C4: ='Owners Info'!F4 -> Edgardo Pison | D4: ='Owners Info'!I4 -> Fixed | E4: ='Owners Info'!J4 -> 45180 | F4: ='Owners Info'!K4 -> MISSING | G4: ='Owners Info'!L4 -> ? | H4: ='Owners Info'!C4 -> ACTIVE | I4: ='Owners Info'!M4 | J4: ='Owners Info'!G4 -> n_pison@yahoo.com | L4: 4
A5: ='Owners Info'!A5 -> Avida Storeys 1 | B5: ='Owners Info'!B5 -> S2 S1 210 | C5: ='Owners Info'!F5 -> Dondon Pison | D5: ='Owners Info'!I5 -> Fixed | E5: ='Owners Info'!J5 -> 45458 | F5: ='Owners Info'!K5 -> 46188 | G5: ='Owners Info'!L5 -> EXPIRED | H5: ='Owners Info'!C5 -> ACTIVE | I5: ='Owners Info'!M5 | J5: ='Owners Info'!G5 -> n_pison@yahoo.com | L5: 5
A6: ='Owners Info'!A6 -> Avida Storeys 1 | B6: ='Owners Info'!B6 -> H S1 506 | C6: ='Owners Info'!F6 -> Bacolod Concept Realty Corp. | D6: ='Owners Info'!I6 -> Fixed | E6: ='Owners Info'!J6 -> 45061 | F6: ='Owners Info'!K6 -> MISSING | G6: ='Owners Info'!L6 -> INACTIVE | H6: ='Owners Info'!C6 -> INACTIVE | I6: ='Owners Info'!M6 | J6: ='Owners Info'!G6 -> n_pison@yahoo.com | L6: 6
A7: ='Owners Info'!A7 -> Avida Storeys 1 | B7: ='Owners Info'!B7 -> Y S1 704 | C7: ='Owners Info'!F7 -> Goldamier Ybera Chua | D7: ='Owners Info'!I7 -> Partnership | E7: ='Owners Info'!J7 -> 45717 | F7: ='Owners Info'!K7 -> 46082 | G7: ='Owners Info'!L7 -> EXPIRED | H7: ='Owners Info'!C7 -> ACTIVE | I7: ='Owners Info'!M7 | J7: ='Owners Info'!G7 -> goldameirchua@gycmarketingopc.com | L7: 7
A8: ='Owners Info'!A8 -> Avida Storeys 2 | B8: ='Owners Info'!B8 -> Y2 S2 203 | C8: ='Owners Info'!F8 -> Ma. Crislyne Mae Espinosa | D8: ='Owners Info'!I8 -> Partnership | E8: ='Owners Info'!J8 -> 45506 | F8: ='Owners Info'!K8 -> 45871 | G8: ='Owners Info'!L8 -> EXPIRED | H8: ='Owners Info'!C8 -> ACTIVE | I8: ='Owners Info'!M8 -> Y2 S2 203 - ESPINOSA.pdf | J8: ='Owners Info'!G8 -> arlandbarvilla@gmail.com | L8: 8
A9: ='Owners Info'!A9 -> Avida Storeys 2 | B9: ='Owners Info'!B9 -> K2 S2 322 | C9: ='Owners Info'!F9 | D9: ='Owners Info'!I9 -> Fixed | E9: ='Owners Info'!J9 -> 45245 | F9: ='Owners Info'!K9 -> MISSING | G9: ='Owners Info'!L9 -> ? | H9: ='Owners Info'!C9 -> ACTIVE | I9: ='Owners Info'!M9 | J9: ='Owners Info'!G9 -> n_pison@yahoo.com | L9: 9
A10: ='Owners Info'!A10 -> Avida Storeys 2 | B10: ='Owners Info'!B10 -> L S2 716 | C10: ='Owners Info'!F10 -> Raymund Trenas | D10: ='Owners Info'!I10 -> Fixed | E10: ='Owners Info'!J10 -> 45180 | F10: ='Owners Info'!K10 -> MISSING | G10: ='Owners Info'!L10 -> ? | H10: ='Owners Info'!C10 -> ACTIVE | I10: ='Owners Info'!M10 | J10: ='Owners Info'!G10 -> raytrenas@gmail.com | L10: 10
A11: ='Owners Info'!A11 -> Avida Storeys 2 | B11: ='Owners Info'!B11 -> T2 S2 703 | C11: ='Owners Info'!F11 -> Leo Paranpan | D11: ='Owners Info'!I11 -> Partnership | E11: ='Owners Info'!J11 -> 45461 | F11: ='Owners Info'!K11 -> 45826 | G11: ='Owners Info'!L11 -> EXPIRED | H11: ='Owners Info'!C11 -> FOR RENEWAL | I11: ='Owners Info'!M11 -> T2 S2 703 - PARANPAN.pdf | J11: ='Owners Info'!G11 -> lparanpan@yahoo.com | L11: 11
A12: ='Owners Info'!A12 -> Avida Tower 1 | B12: ='Owners Info'!B12 -> D T1 917 | C12: ='Owners Info'!F12 -> Robert Stanley Po | D12: ='Owners Info'!I12 -> Partnership | E12: ='Owners Info'!J12 -> 45809 | F12: ='Owners Info'!K12 -> 46174 | G12: ='Owners Info'!L12 -> EXPIRED | H12: ='Owners Info'!C12 -> ACTIVE | I12: ='Owners Info'!M12 | J12: ='Owners Info'!G12 -> cltpo@icloud.com | L12: 12
A13: ='Owners Info'!A13 -> Avida Tower 1 | B13: ='Owners Info'!B13 -> C3 T1 428 | C13: ='Owners Info'!F13 -> Ramona Beck | D13: ='Owners Info'!I13 -> 75/25 Partner | E13: ='Owners Info'!J13 -> 45635 | F13: ='Owners Info'!K13 -> 46000 | G13: ='Owners Info'!L13 -> EXPIRED | H13: ='Owners Info'!C13 -> ACTIVE | I13: ='Owners Info'!M13 | J13: ='Owners Info'!G13 -> mona_beck2001@yahoo.com | L13: 13
... A20: ='Owners Info'!A20 -> Avida Tower 2 | B20: ='Owners Info'!B20 -> R T2 1423 | C20: ='Owners Info'!F20 -> Irene Lachica | D20: ='Owners Info'!I20 -> Fixed | E20: ='Owners Info'!J20 -> 45184 | F20: ='Owners Info'!K20 -> MISSING | G20: ='Owners Info'!L20 -> ? | H20: ='Owners Info'!C20 -> ACTIVE | I20: ='Owners Info'!M20 | J20: ='Owners Info'!G20 -> irene.lachica@yahoo.com | L20: 20
A21: ='Owners Info'!A22 -> Avida Tower 2 | B21: ='Owners Info'!B22 -> B2 T2 108 | C21: ='Owners Info'!F22 -> Edward Espinosa | D21: ='Owners Info'!I22 -> Fixed | E21: ='Owners Info'!J22 -> 45294 | F21: ='Owners Info'!K22 -> MISSING | G21: ='Owners Info'!L22 -> ? | H21: ='Owners Info'!C22 -> ACTIVE | I21: ='Owners Info'!M22 | J21: ='Owners Info'!G22 -> mariespinosa3185@gmail.com | L21: 21
A22: ='Owners Info'!A23 -> Avida Tower 2 | B22: ='Owners Info'!B23 -> F T2 1020 | C22: ='Owners Info'!F23 -> Kathreen Socorro Piamonte | D22: ='Owners Info'!I23 -> Fixed | E22: ='Owners Info'!J23 -> 45022 | F22: ='Owners Info'!K23 -> MISSING | G22: ='Owners Info'!L23 -> ? | H22: ='Owners Info'!C23 -> ACTIVE | I22: ='Owners Info'!M23 | J22: ='Owners Info'!G23 | L22: 22
A23: ='Owners Info'!A24 -> Avida Tower 2 | B23: ='Owners Info'!B24 -> N T2 421 | C23: ='Owners Info'!F24 -> Roberto Gelvezon | D23: ='Owners Info'!I24 -> Fixed | E23: ='Owners Info'!J24 -> 45143 | F23: ='Owners Info'!K24 | G23: ='Owners Info'!L24 | H23: ='Owners Info'!C24 -> ACTIVE | I23: ='Owners Info'!M24 | J23: ='Owners Info'!G24 | L23: 23
A24: ='Owners Info'!A26 -> Avida Tower 2 | B24: ='Owners Info'!B26 -> X T2 1021 | C24: ='Owners Info'!F26 -> Michael Borro | D24: ='Owners Info'!I26 -> Fixed | E24: ='Owners Info'!J26 -> 45107 | F24: ='Owners Info'!K26 -> 46203 | G24: ='Owners Info'!L26 -> EXPIRED | H24: ='Owners Info'!C26 -> ACTIVE | I24: ='Owners Info'!M26 | J24: ='Owners Info'!G26 | L24: 24
A25: ='Owners Info'!A27 -> Avida Tower 2 | B25: ='Owners Info'!B27 -> H2 T2 521 | C25: ='Owners Info'!F27 -> Maria Rita Jardiolin | D25: ='Owners Info'!I27 -> Fixed | E25: ='Owners Info'!J27 -> 45294 | F25: ='Owners Info'!K27 -> MISSING | G25: ='Owners Info'!L27 -> ? | H25: ='Owners Info'!C27 -> ACTIVE | I25: ='Owners Info'!M27 | J25: ='Owners Info'!G27 -> Ritaj241@yahoo.com | L25: 25
A26: ='Owners Info'!A28 -> Avida Tower 2 | B26: ='Owners Info'!B28 -> Q2 T2 1221 | C26: ='Owners Info'!F28 -> Maria Grace Puertollano | D26: ='Owners Info'!I28 -> Partnership | E26: ='Owners Info'!J28 | F26: ='Owners Info'!K28 | G26: ='Owners Info'!L28 -> INACTIVE | H26: ='Owners Info'!C28 -> INACTIVE | I26: ='Owners Info'!M28 | J26: ='Owners Info'!G28 -> graceuybico@gmail.com | L26: 26
A27: ='Owners Info'!A29 -> Avida Tower 2 | B27: ='Owners Info'!B29 -> A T2 322 | C27: ='Owners Info'!F29 -> Aaron James Sales | D27: ='Owners Info'!I29 -> 85/15 Partner | E27: ='Owners Info'!J29 -> 45729 | F27: ='Owners Info'!K29 -> 45821 | G27: ='Owners Info'!L29 -> EXPIRED | H27: ='Owners Info'!C29 -> ACTIVE | I27: ='Owners Info'!M29 | J27: ='Owners Info'!G29 -> Aaronsales.j@gmail.com | L27: 27
A28: ='Owners Info'!A30 -> Avida Tower 2 | B28: ='Owners Info'!B30 -> # T2 209 | C28: ='Owners Info'!F30 -> Fredilyn Samoro/Katrina Samoro | D28: ='Owners Info'!I30 -> 85/15 Partner | E28: ='Owners Info'!J30 -> 45769 | F28: ='Owners Info'!K30 -> 45961 | G28: ='Owners Info'!L30 -> EXPIRED | H28: ='Owners Info'!C30 -> ACTIVE | I28: ='Owners Info'!M30 | J28: ='Owners Info'!G30 | L28: 28
A29: ='Owners Info'!A31 -> Avida Tower 3 | B29: ='Owners Info'!B31 -> D2 T3 626 | C29: ='Owners Info'!F31 -> Donnave Caramat | D29: ='Owners Info'!I31 -> Fixed | E29: ='Owners Info'!J31 -> 45294 | F29: ='Owners Info'!K31 -> MISSING | G29: ='Owners Info'!L31 -> ? | H29: ='Owners Info'!C31 -> ACTIVE | I29: ='Owners Info'!M31 | J29: ='Owners Info'!G31 -> dgcaramat12@gmail.com | L29: 29
A30: ='Owners Info'!A33 -> Avida Tower 3 | B30: ='Owners Info'!B33 -> I T3 725 | C30: ='Owners Info'!F33 -> Mechelle Balasa Rey | D30: ='Owners Info'!I33 -> Fixed | E30: ='Owners Info'!J33 -> 45070 | F30: ='Owners Info'!K33 -> MISSING | G30: ='Owners Info'!L33 -> INACTIVE | H30: ='Owners Info'!C33 -> INACTIVE | I30: ='Owners Info'!M33 | J30: ='Owners Info'!G33 -> jayson12mendoza15@gmail.com | L30: 30
A31: =#REF! -> #REF! | B31: =#REF! -> #REF! | C31: =#REF! -> #REF! | D31: =#REF! -> #REF! | E31: =#REF! -> #REF! | F31: =#REF! -> #REF! | G31: =#REF! -> #REF! | H31: =#REF! -> #REF! | ... J31: =#REF! -> #REF! | L31: 31
A32: ='Owners Info'!A34 -> Avida Tower 3 | B32: ='Owners Info'!B34 -> B3 T3 1011 | C32: ='Owners Info'!F34 -> Gutierrez Dev. Company | D32: ='Owners Info'!I34 -> 75/25 Partner | E32: ='Owners Info'!J34 -> 45611 | F32: ='Owners Info'!K34 -> MISSING | G32: ='Owners Info'!L34 -> ? | H32: ='Owners Info'!C34 -> ACTIVE | I32: ='Owners Info'!M34 | J32: ='Owners Info'!G34 -> gutierrezdevelopment@gmail.com | L32: 32
A33: ='Owners Info'!A35 -> Avida Tower 3 | B33: ='Owners Info'!B35 -> W2 T3 207 | C33: ='Owners Info'!F35 -> Pancho Bringas / Christine Magallanes | D33: ='Owners Info'!I35 -> Partnership | E33: ='Owners Info'!J35 -> 45506 | F33: ='Owners Info'!K35 -> 45871 | G33: ='Owners Info'!L35 -> EXPIRED | H33: ='Owners Info'!C35 -> ACTIVE | I33: ='Owners Info'!M35 | J33: ='Owners Info'!G35 -> Ceee_m@yahoo.com | L33: 33
A34: ='Owners Info'!A36 -> Avida Tower 3 | B34: ='Owners Info'!B36 -> X2 T3 528 | C34: ='Owners Info'!F36 -> Pancho Bringas / Christine Magallanes | D34: ='Owners Info'!I36 -> Partnership | E34: ='Owners Info'!J36 -> 45506 | F34: ='Owners Info'!K36 -> 45871 | G34: ='Owners Info'!L36 -> EXPIRED | H34: ='Owners Info'!C36 -> ACTIVE | I34: ='Owners Info'!M36 | J34: ='Owners Info'!G36 -> Ceee_m@yahoo.com | L34: 34
A35: ='Owners Info'!A37 -> Avida Tower 3 | B35: ='Owners Info'!B37 -> Z2 T3 526 | C35: ='Owners Info'!F37 -> Czarina Ngan | D35: ='Owners Info'!I37 -> 85/15 Partner | E35: ='Owners Info'!J37 -> 45769 | F35: ='Owners Info'!K37 -> 45869 | G35: ='Owners Info'!L37 -> EXPIRED | H35: ='Owners Info'!C37 -> ACTIVE | I35: ='Owners Info'!M37 | J35: ='Owners Info'!G37 -> e43eee3esdwafcfvfcffvgvgrdcrxseexttfddfddz;;p-p-p= | L35: 35
A36: ='Owners Info'!A38 -> Avida Tower 3 | B36: ='Owners Info'!B38 -> M2 T3 424 | C36: ='Owners Info'!F38 -> Leyson San Juan | D36: ='Owners Info'!I38 -> Partnership | E36: ='Owners Info'!J38 -> 45811 | F36: ='Owners Info'!K38 -> 46176 | G36: ='Owners Info'!L38 -> EXPIRED | H36: ='Owners Info'!C38 -> ACTIVE | I36: ='Owners Info'!M38 | J36: ='Owners Info'!G38 -> leyson37@gmail.com | L36: 36
A37: ='Owners Info'!A39 -> Avida Tower 3 | B37: ='Owners Info'!B39 -> N2 T3 426 | C37: ='Owners Info'!F39 -> Leyson San Juan | D37: ='Owners Info'!I39 -> Partnership | E37: ='Owners Info'!J39 -> 45811 | F37: ='Owners Info'!K39 -> 46176 | G37: ='Owners Info'!L39 -> EXPIRED | H37: ='Owners Info'!C39 -> ACTIVE | I37: ='Owners Info'!M39 | J37: ='Owners Info'!G39 -> leyson37@gmail.com | L37: 37
A38: ='Owners Info'!A40 -> Avida Tower 3 | B38: ='Owners Info'!B40 -> O2 T3 826 | C38: ='Owners Info'!F40 -> Leyson San Juan | D38: ='Owners Info'!I40 -> Partnership | E38: ='Owners Info'!J40 -> 45811 | F38: ='Owners Info'!K40 -> 46176 | G38: ='Owners Info'!L40 -> EXPIRED | H38: ='Owners Info'!C40 -> ACTIVE | I38: ='Owners Info'!M40 -> AT T3 826 - SAN JUAN (RENEWAL).pdf | J38: ='Owners Info'!G40 -> leyson37@gmail.com | L38: 38
A39: ='Owners Info'!A41 -> Avida Tower 4 | B39: ='Owners Info'!B41 -> J2 T4 117 | C39: ='Owners Info'!F41 -> Cherry Villa / Jeseryl Villa | D39: ='Owners Info'!I41 -> 85/15 Partner | E39: ='Owners Info'!J41 -> 45809 | F39: ='Owners Info'!K41 -> 46174 | G39: ='Owners Info'!L41 -> EXPIRED | H39: ='Owners Info'!C41 -> ACTIVE | I39: ='Owners Info'!M41 -> AT T4 117 - PINK/VILLA.pdf | J39: ='Owners Info'!G41 -> kixmd@yahoo.com | L39: 39
A40: ='Owners Info'!A42 -> Bernwood Tower | B40: ='Owners Info'!B42 -> BT 1 1222 | C40: ='Owners Info'!F42 -> Ruth Santisteban Serrato | D40: ='Owners Info'!I42 -> Partnership | E40: ='Owners Info'!J42 -> 45748 | F40: ='Owners Info'!K42 -> 45930 | G40: ='Owners Info'!L42 -> EXPIRED | H40: ='Owners Info'!C42 -> ACTIVE | I40: ='Owners Info'!M42 | J40: ='Owners Info'!G42 -> ruthserrato@yahoo.com | L40: 40
A41: ='Owners Info'!A43 -> Lafayette | B41: ='Owners Info'!B43 -> 6 LPS 16S | C41: ='Owners Info'!F43 -> Christine Ladigohon | D41: ='Owners Info'!I43 -> Partnership | E41: ='Owners Info'!J43 -> 45800 | F41: ='Owners Info'!K43 -> 46349 | G41: ='Owners Info'!L43 -> 88 | H41: ='Owners Info'!C43 -> ACTIVE | I41: ='Owners Info'!M43 -> LPS 16S - LADIGOHON.pdf | J41: ='Owners Info'!G43 -> christineladigohon@gmail.com | L41: 41
A42: ='Owners Info'!A44 -> Lafayette | B42: ='Owners Info'!B44 -> 42 LPS 5E | C42: ='Owners Info'!F44 -> Mary Jean Bearneza | D42: ='Owners Info'!I44 -> 85/15 Partner | E42: ='Owners Info'!J44 -> 45805 | F42: ='Owners Info'!K44 -> 46170 | G42: ='Owners Info'!L44 -> EXPIRED | H42: ='Owners Info'!C44 -> ACTIVE | I42: ='Owners Info'!M44 -> LPS 5E - BEARNEZA.pdf | J42: ='Owners Info'!G44 -> cornerhome99@gmail.com | L42: 42
A43: ='Owners Info'!A45 -> Lafayette | B43: ='Owners Info'!B45 -> 25 LPS 8S | C43: ='Owners Info'!F45 -> Julius Jacomille | D43: ='Owners Info'!I45 -> 75/25 Partner | E43: ='Owners Info'!J45 -> 45579 | F43: ='Owners Info'!K45 -> 45944 | G43: ='Owners Info'!L45 -> EXPIRED | H43: ='Owners Info'!C45 -> ACTIVE | I43: ='Owners Info'!M45 -> 25 LPS 8S - JACOMILLE.pdf | J43: ='Owners Info'!G45 -> rentwithus.abc@gmail.com | L43: 43
... A76: ='Owners Info'!A78 -> Saint Dominique | B76: ='Owners Info'!B78 -> 7 SD SW 9G | C76: ='Owners Info'!F78 -> Noah Montenegro | D76: ='Owners Info'!I78 -> Partnership | E76: ='Owners Info'!J78 -> 45737 | F76: ='Owners Info'!K78 -> 46102 | G76: ='Owners Info'!L78 -> EXPIRED | H76: ='Owners Info'!C78 -> ACTIVE | I76: ='Owners Info'!M78 | J76: ='Owners Info'!G78 -> noahmontenegro@optimum.net | L76: 76
A77: ='Owners Info'!A79 -> Saint Dominique | B77: ='Owners Info'!B79 -> 29 SD SW 3I | C77: =#REF! -> #REF! | D77: ='Owners Info'!I79 -> Partnership | E77: ='Owners Info'!J79 -> 45818 | F77: ='Owners Info'!K79 -> 46183 | G77: ='Owners Info'!L79 -> EXPIRED | H77: ='Owners Info'!C79 -> ACTIVE | I77: ='Owners Info'!M79 -> SD SW 3I - MATORRES.pdf | J77: ='Owners Info'!G79 -> preciousfematorres@gmail.com | L77: 77
A78: ='Owners Info'!A80 -> Saint Honore | B78: ='Owners Info'!B80 -> 43 SH NW 5T | C78: ='Owners Info'!F79 -> Ma Precious Fe Matorres | D78: ='Owners Info'!I80 -> 85/15 Partner | E78: ='Owners Info'!J80 -> 45805 | F78: ='Owners Info'!K80 -> 46170 | G78: ='Owners Info'!L80 -> EXPIRED | H78: ='Owners Info'!C80 -> ACTIVE | I78: ='Owners Info'!M80 -> SH NW 5T - BEARNEZA.pdf | J78: ='Owners Info'!G80 -> cornerhome99@gmail.com | L78: 78
...

Sheet OI-Old
A1: Building | B1: Status | C1: Property | D1: Unit Type | E1: Unit Owner | F1: Email | G1: Contact Number | H1: Classification | I1: Effective Date | J1: Expiry Date | K1: Near Expiry Tracker | L1: Contract | M1: TYPE OF PARTNERSHIP | N1: AIRBNB | O1: BOOKING .COM | P1: AGODA | Q1: HOSTEEVA | R1: YOUR RENTALS | S1: TRIP.COM | T1: INVENTORY LIST
A2: Saint Honore | B2: ACTIVE | C2: 1 SH NW 8C | D2: Studio | E2: Jan Cupid Musa | F2: jancupidmusa@gmail.com | G2: +1 (469) 974-5979 | H2: Partnership | I2: 45730 | J2: 45914 | L2: 1 SH NW 8C - MUSA.pdf | N2: 1 SH NW 8C | O2: 1 Parisian Charm Hideaway | P2: 1 SH NW 8C
A3: Saint Honore | B3: ACTIVE | C3: 4 SH 5M SW | D3: 1-Bedroom | E3: Charizzma Go | F3: gochusc@gmail.com | H3: Fixed | I3: 45859 | J3: 46224 | N3: 4 SH 5M SW | O3: 4 Majestic View | P3: 4 SH 5M SW
A4: Saint Honore | B4: ACTIVE | C4: 26 SH SW 7G | L4: 26 SH SW 7G - JACOMILLE.pdf | N4: 26 SH SW 7G | O4: 26 Affordable Luxury Studio | P4: 26 SH SW 7G
A5: Saint Honore | B5: INACTIVE | C5: 6 SH SW 5J | D5: 2-Bedroom | E5: Lilanie Young | F5: lilanieyoung@gmail.com | G5: 639171228861 | H5: Partnership | I5: 45456 | J5: 45821 | L5: 6 SH SW 5J - YOUNG.pdf | N5: 6 SH SW 5J | O5: 6 Stylish Escape for Groups
A6: Saint Honore | B6: INACTIVE | C6: 17 SH SW 6O | N6: 17 SH SW 6O
A7: Saint Honore | B7: INACTIVE | C7: 15 LPS 10-O | D7: 1-Bedroom | E7: Michael Limsiaco | F7: limsiacomichael@yahoo.com | G7: 639189012626 | H7: Partnership | I7: 45503 | J7: 45868 | L7: 15 LPS 10-O - LIMSIACO.pdf
A8: Saint Honore | B8: INACTIVE | C8: 21 SH NW 6A | D8: 2-Bedroom | E8: Ernesto Tuvida | F8: hjameprestosa@yahoo.com | G8: 639054738567 | H8: Partnership | I8: 45579 | J8: 45944 | L8: 21 SH NW 6A - TUVIDA.pdf | N8: 21 SH NW 6A
A9: Saint Honore | B9: ACTIVE | C9: 24 LPS 9PQ | D9: 1-Bedroom | E9: Risty Durbin | F9: ristyd@yahoo.com | H9: Partnership | I9: 45566 | J9: 45931 | L9: 24 LPS 9PQ - DURBIN.pdf
A10: Saint Dominique | B10: ACTIVE | C10: 7 SD 9G SW | D10: Studio | E10: Noah Montenegro | F10: noahmontenegro@optimum.net | G10: +1 (203) 219-1427 | H10: Partnership | I10: 45737 | J10: 46102 | N10: 7 SD 9G SW | O10: 7 Metro View Studio | P10: 7 SD 9G SW
A11: Saint Dominique | B11: ACTIVE | C11: 23 SD SW 8C | N11: 23 SD SW 8C | O11: 23 Comfy Nest for Three | P11: 23 SD SW 8C
A12: Saint Dominique | B12: ACTIVE | C12: 33 SD SW 7I | D12: Studio | E12: Hyacinth Faraon | F12: Hyacinth.9@hotmail.com | H12: Partnership | I12: 45673 | J12: 46038 | N12: 33 SD SW 7i | O12: 33 Elegant City Studio | P12: 33 SD SW 7I
A13: Saint Dominique | B13: ACTIVE | C13: 37 SD NW 5F | D13: Studio | E13: Cesar Mercado | F13: meres044@yahoo.com | G13: 639156392337 | H13: Partnership | I13: 45714 | J13: 45895 | L13: 37 SD NW 5F - MARICAR.pdf | N13: 37 SD NW 5F | O13: 37 Elegant & Cozy | P13: 37 SD NW 5F
A14: Saint Dominique | B14: ACTIVE | C14: 30 SD NW 8B | D14: Studio | E14: Ramel Uy | F14: Uy_ramel@yahoo.com | H14: Partnership | I14: 45245 | J14: MISSING EXPIRY DATE | N14: 30 SD NW 8B | O14: 30 Luxe City Studio | P14: 30 SD NW 8B
A15: Saint Dominique | B15: ACTIVE | C15: 29 SD SW 3I | D15: Studio | E15: Ma Precious Fe Matorres | F15: preciousfematorres@gmail.com | G15: 639610926625 | H15: Partnership | I15: 45818 | J15: 46183 | L15: 29 SD SW 3i - MATORRES.pdf | N15: 29 SD SW 3i | O15: 29 Chic Studio Escape | P15: 29 SD SW 3I
A16: One Madison Place | B16: ACTIVE | C16: 2 OMP T1 8D | D16: Studio | E16: Risty Durbin | F16: ristyd@yahoo.com | H16: Partnership | I16: 45525 | J16: 45890 | N16: 2 OMP T1 8D | O16: 2 Contemporary Comfort | P16: 2 OMP T1 8D
A17: One Madison Place | B17: ACTIVE | C17: 3 OMP T3 10-O | D17: Studio | E17: Cynthia Mansueto | F17: cynthiamansueto@yahoo.com.ph | G17: 639263194338 | H17: Partnership | I17: 45624 | J17: 45989 | N17: 3 OMP T3 10-O | O17: 3 Iloilo's Dream Studio | P17: 3 OMP T3 10-O
A18: One Madison Place | B18: ACTIVE | C18: 12 OMP T3 9K | D18: 1-Bedroom | E18: Arlene Tirador | F18: febgirl2691@yahoo.com.ph | G18: 639177995554 | H18: Partnership | I18: 45422 | J18: 45787 | L18: 12 OMP T3 9K - TAN.pdf | N18: 12 OMP T3 9K | O18: 12 Modern Sanctuary | P18: 12 OMP T3 9K
A19: One Madison Place | B19: ACTIVE | C19: 19 OMP T1 4E | D19: Studio | E19: Emmanuel Capacio | F19: emmanuelcapacio@gmail.com | H19: Partnership | I19: 45758 | J19: 46123 | L19: 19 OMP T1 4E - JAVELLANA.pdf | N19: 19 OMP T1 4E | O19: 19 Cityscape Views | P19: 19 OMP T1 4E
A20: One Madison Place | B20: ACTIVE | C20: 20 OMP T1 9S | D20: 1-Bedroom | E20: Charizzma Go | F20: gochusc@gmail.com | H20: Fixed | I20: 45750 | J20: 46115 | L20: 20 OMP T1 9S - FARAON.pdf | N20: 20 OMP T1 9S | O20: 20 Pool View Studio Bliss | P20: 20 OMP T1 9S
A21: One Madison Place | B21: ACTIVE | C21: 27 OMP T3 5N | D21: Studio | E21: Julius Jacomille | F21: rentwithus.abc@gmail.com | H21: Partnership | I21: 45579 | J21: 45944 | N21: 27 OMP T3 5N | O21: 27 Chic and Spacious Studio | P21: 27 OMP T3 5N
A22: One Madison Place | B22: ACTIVE | C22: 28 OMP T3 5M | D22: Studio | E22: Julius Jacomille | F22: rentwithus.abc@gmail.com | H22: Partnership | L22: 28 OMP T3 5M - MANSUETO.pdf | N22: 28 OMP T3 5M | O22: 28 Central Location King Studio | P22: 28 OMP T3 5M
A23: One Madison Place | B23: ACTIVE | C23: 31 OMP T2 4B | D23: Studio | E23: Anjo Diansay | F23: anjodiansay@gmail.com | G23: +1 (424) 385-1369 | H23: Partnership | I23: 45635 | J23: 46000 | L23: 31 OMP T2 4B - ALIMPOYO.pdf | N23: 31 OMP T2 4B | O23: 31 Budget-Friendly Studio | P23: 31 OMP T2 4B
A24: One Madison Place | B24: ACTIVE | C24: 38 OMP T1 9N | D24: Studio | E24: Ibrahim Khalilullah Maricar | F24: ibrahim.maricar@outlook.com | H24: Partnership | I24: 45716 | J24: 46081 | N24: 38 OMP T1 9N | O24: 38 Cozy Urban Hideaway | P24: 38 OMP T1 9N
A25: One Madison Place | B25: ACTIVE | C25: 32 OMP T3 10E | D25: Studio | E25: Rodel Alimpoyo | F25: rodel5alimpoyo@yahoo.com.ph | H25: Partnership | I25: 45639 | J25: 46004 | L25: 32 OMP T3 10E - FARAON.pdf | N25: 32 OMP T3 10E | O25: 32 Best Value Family Suite | P25: 32 OMP T3 10E
A26: One Madison Place | B26: ACTIVE | C26: 40 OMP T1 7U | D26: Studio | E26: Millicent Tiu | F26: millicent.sy.tiu@gmail.com | N26: 40 OMP T1 7U | O26: 40 Minimalist Haven | P26: 40 OMP T1 7U
B27: ACTIVE | C27: 11 OMP T2 5P | D27: Studio | E27: Ernestine Valle | F27: enitsenrevalle@gmail.com | G27: 639178593048 | H27: Partnership | I27: 45444 | J27: 45809 | L27: 11 OMP T2 5P - VALLE.pdf | N27: 11 OMP T2 5P | O27: 11 Warm and Cozy Studio | P27: 11 OMP T2 5P
A28: One Madison Place | B28: IN PROGRESS | C28: 41 OMP T3 10K | D28: Studio | E28: Ibrahim Kabeer | F28: ibrahimmaricar@outlook.com | H28: Partnership | I28: 45778 | J28: 46143 | L28: OMP T3 10K
A29: Lafayette | B29: ACTIVE | C29: 5 LPS 16T | D29: Studio | E29: Esther Palmares | F29: Esjoyp@aol.com | G29: 639178989043 | H29: Partnership | I29: 45670 | J29: 46035 | L29: LPS 16T - PALMARES.pdf | N29: 5 LPS 16T | O29: 5 Modern Chic Studio | P29: 5 LPS 16T
A30: Lafayette | B30: ACTIVE | C30: 6 LPS 16S | D30: Studio | E30: Christine Ladigohon | F30: christineladigohon@gmail.com | G30: 9291818824 | H30: Partnership | I30: 45740 | J30: 46166 | N30: 6 LPS 16S | O30: 6 Simple Pearl Retreat | P30: 6 LPS 16S
A31: Lafayette | B31: ACTIVE | C31: 15 LPS 10-O | D31: Studio | E31: Ira Villanueva | F31: villanueva_ira@yahoo.com | G31: 639173052499 | H31: Partnership | I31: 45474 | J31: 45839 | N31: 15 LPS 10-O | O31: 15 Elegant Urban Suite | P31: 15 LPS 10-O
A32: Lafayette | B32: ACTIVE | C32: 16 LPS 15X | D32: Studio | E32: Risty Durbin | F32: ristyd@yahoo.com | H32: Partnership | I32: 45495 | J32: 45860 | L32: 16 LPS 15X - SOLINAP.pdf | N32: 16 LPS 15X | O32: 16 Cozy and Spacious Studio | P32: 16 LPS 15X
A33: Lafayette | B33: ACTIVE | C33: 18 LPS 9R | D33: Studio | E33: Euniel Solinap | F33: euniel.md@gmail.com | G33: 639173208884 | H33: Partnership | I33: 45509 | J33: 45874 | L33: 18 LPS 9R - DURBIN.pdf | N33: 18 LPS 9R | O33: 18 Warm Studio Oasis | P33: 18 LPS 9R
A34: Lafayette | B34: ACTIVE | C34: 22 LPS 8J | D34: Studio | E34: Hyacinth Faraon | F34: Hyacinth.9@hotmail.com | H34: Partnership | I34: 45524 | J34: 45889 | L34: 22 LPS 8J -ZAPANTA.pdf | N34: 22 LPS 8J | O34: 22 Luxurious 1-Bedroom Apartment | P34: 22 LPS 8J
A35: Lafayette | B35: ACTIVE | C35: 24 LPS 9PQ | D35: 1-Bedroom | E35: Adonis Zapanta | F35: dimple_email2@yahoo.com | H35: Partnership | I35: 45531 | J35: 45896 | N35: 24 LPS 9PQ | O35: 24 Modern 1-Bedroom Minimalist Sanctuary | P35: 24 LPS 9PQ
A36: Lafayette | B36: ACTIVE | C36: 25 LPS 8S | D36: Studio | E36: Maricel Hoy | F36: maricelhoy@yahoo.com | H36: Partnership | I36: 45791 | J36: 46156 | L36: 25 LPS 8S - JACOMILLE.pdf | N36: 25 LPS 8S | O36: 25 Central Luxury Studio | P36: 25 LPS 8S
A37: Lafayette | B37: ACTIVE | C37: 34 LPS 5Z | D37: Studio | E37: Antonio Geronca | F37: jadgeronca@gmail.com, ems1215@ymail.com | G37: 639173177203 | H37: Partnership | I37: 45688 | J37: 46053 | L37: 34 LPS 5Z - BELICENA.pdf | N37: 34 LPS 5Z | O37: 34 Retro Chic Studio | P37: 34 LPS 5Z
A38: Lafayette | B38: ACTIVE | C38: 35 LPS 5Y | D38: Studio | E38: Maria Emily Belicena | F38: emilybelicena@gmail.com | G38: 639185702183 | H38: Partnership | I38: 45707 | J38: 46010 | L38: 35 LPS 5Y - BELICENA.pdf | N38: 35 LPS 5Y | O38: 35 Adorable Studio | P38: 35 LPS 5Y
A39: Lafayette | B39: ACTIVE | C39: 36 LPS 3T | D39: Studio | E39: Maria Emily Belicena/Beatriz Karina Belicena | F39: emilybelicena@gmail.com | G39: 639185702183 | H39: Partnership | I39: 45707 | J39: 46010 | L39: 36 LPS 3T - MERCADO.pdf | N39: 36 LPS 3T | O39: 36 Executive Garden Suite | P39: 36 LPS 3T
A40: The Palladium | B40: ACTIVE | C40: 8 TP NW 21B | D40: Executive Studio | E40: Amy Lapating | N40: 8 TP NW 21B | O40: 8 Skyline Sunset Suite | P40: 8 TP NW 21B
...

Sheet Deposit Accounts & Emails
A1: Property | B1: Bank | C1: Account Name | D1: Account Number | E1: Email | F1: Due Date
A2: One Madison Place | B2: Union Bank of the Philippines | C2: One Madison Place Condominium Association | D2: 0012-4003-6593 | E2: onemadisonplace.ao2@fopm.com.ph | F2: Every 15th
A3: Saint Honore & Saint Dominique | B3: Union Bank of the Philippines | C3: SHSD Condominium Association Inc. | D3: 0027-7001-9813 | E3: billing.sthonorestdominique@asia-affinity.com | F3: Every 20th
A4: The Palladium | B4: Union Bank of the Philippines | C4: The Palladium Condominium Association Inc. | D4: 0027-7001-7336 | E4: billing.palladium@asia-affinity.com | F4: Every 20th
A5: WV Towers | B5: BDO Unibank Inc | C5: Westernland Property Development Inc. | D5: 0028-1801-3409 | E5: wvtowers1.2@gmail.com | F5: Every 30th
A6: BA Technology (WiFi) | B6: Gcash | C6: BA Technology | D6: (+63) 994 205 0180 | E6: state unit number in notes | F6: Every 15th
A7: SMDC Style Residences | B7: BDO Unibank Inc | C7: Style Residences Condominium Corporation | D7: 0103-6801-0791 | E7: style.billing@greenmist.ph | F7: Every 30th
A8: One Spatial Iloilo | B8: Eastwest Bank | C8: One Spatial Iloilo Condominium Corp | D8: 2000-3028-7807 | E8: upload to pocket floor app | F8: Every 15th

Sheet Rates
A1: STUDIO
A2: Property | B2: 2 pax | C2: 3 pax | D2: 4 pax | E2: 5 pax
A3: Avida Towers | D3: - | E3: -
D4: - | E4: -
A5: Bernwood Towers
A7: People's Condo | B7: ] | D7: - | E7: -
D8: - | E8: -
A9: St. Honore & St. Dominique | B9: 1999 | C9: 2299 | D9: 2599 | E9: 2899
B10: 2100 | C10: 2400 | D10: 2700 | E10: 3000
A11: Lafayette | B11: 1999 | C11: 2299 | D11: 2599 | E11: 2899
B12: 2100 | C12: 2400 | D12: 2700 | E12: 3000
A15: SMDC STYLE | B15: 1999 | C15: 2299 | D15: 2599 | E15: -
B16: 2100 | C16: 2400 | D16: 2700 | E16: -
A17: One Madison | B17: 1999 | C17: 2299 | D17: 2599
B18: 2100 | C18: 2400 | D18: 2700
A19: The Palladium
A22: 1 BEDROOM
A23: Property | B23: 2 pax | C23: 3 pax | D23: 4 pax | E23: 5 pax | F23: 6 pax
A24: WV Towers | B24: 1800 | C24: =B24+350 -> 2150 | D24: =B24+700 -> 2500
B25: 2050 | C25: =B25+350 -> 2400 | D25: =B25+700 -> 2750
A26: Avida Towers | B26: 1800 | C26: =B26+350 -> 2150 | D26: =B26+700 -> 2500 | E26: =B26+1050 -> 2850 | F26: =B26+1400 -> 3200
B27: 2050 | C27: =B27+350 -> 2400 | D27: =B27+700 -> 2750 | E27: =B27+1050 -> 3100 | F27: =B27+1400 -> 3450
A28: Lafayette | B28: 2600 | C28: =B28+350 -> 2950 | D28: =B28+700 -> 3300 | E28: =B28+1050 -> 3650 | F28: =B28+1400 -> 4000
B29: 2850 | C29: =B29+350 -> 3200 | D29: =B29+700 -> 3550 | E29: =B29+1050 -> 3900 | F29: =B29+1400 -> 4250
A30: The Palladium | B30: 2600 | C30: =B30+350 -> 2950 | D30: =B30+700 -> 3300 | E30: =B30+1050 -> 3650 | F30: =B30+1400 -> 4000
B31: 2850 | C31: =B31+350 -> 3200 | D31: =B31+700 -> 3550 | E31: =B31+1050 -> 3900 | F31: =B31+1400 -> 4250
A32: St. Honore & St. Dominique | B32: 2600 | C32: =B32+350 -> 2950 | D32: =B32+700 -> 3300 | E32: =B32+1050 -> 3650 | F32: =B32+1400 -> 4000
B33: 2850 | C33: =B33+350 -> 3200 | D33: =B33+700 -> 3550 | E33: =B33+1050 -> 3900 | F33: =B33+1400 -> 4250
A35: 2 BEDROOMS
A36: Property | B36: 2 pax | C36: 3 pax | D36: 4 pax | E36: 5 pax | F36: 6 pax | G36: 7 pax | H36: 8 pax
A37: SMDC | B37: 2500 | C37: 2800 | D37: 3100 | E37: 3600 | F37: - | G37: - | H37: -
B38: 2750 | C38: 3050 | D38: 3350 | E38: 3650 | F38: - | G38: - | H38: -
A39: Avida (small) | B39: 2600 | C39: 2600 | D39: 2850 | E39: =D39+350 -> 3200 | F39: =D39+700 -> 3550 | G39: - | H39: -
B40: 2850 | C40: 2850 | D40: 2850 | E40: =D40+350 -> 3200 | F40: =D40+700 -> 3550 | G40: - | H40: -
A41: Avida (big) | B41: 2700 | C41: 2700 | D41: 2700 | E41: =D41+350 -> 3050 | F41: =D41+700 -> 3400 | G41: =D41+1050 -> 3750 | H41: =D41+1400 -> 4100
B42: 2950 | C42: 2950 | D42: 2950 | E42: =D42+350 -> 3300 | F42: =D42+700 -> 3650 | G42: =D42+1050 -> 4000 | H42: =D42+1400 -> 4350
A43: Laffayete | B43: 3500 | C43: 3800 | D43: 4100 | E43: 4400 | F43: 4700 | G43: 5000 | H43: 5300
B44: 3950 | C44: 4250 | D44: 4550 | E44: 4850 | F44: 5150 | G44: 5450 | H44: 5750
A45: Saint H & D | B45: 3000 | C45: 3000 | D45: 3000 | E45: 3350 | F45: =D45+700 -> 3700 | G45: =D45+1050 -> 4050 | H45: =D45+1400 -> 4400
B46: 3250 | C46: 3250 | D46: 3250 | E46: =D46+350 -> 3600 | F46: =D46+700 -> 3950 | G46: =D46+1050 -> 4300 | H46: =D46+1400 -> 4650
...

Sheet Extras
B1: Charge | C1: Cost
A2: Extra Person | B2: 300
A4: EARLY CHECK IN
A5: 0.54166667 | B5: 300
A6: 0.58333333 | B6: 250
A7: 0.60416667 | B7: FREE
A8: LATE CHECK OUT
A9: 0.48958333 | B9: FREE
A10: 0.5 | B10: 300
A11: 0.54166667 | B11: 300
A12: 0.58333333 | B12: 500
A14: Day use (8 hours) | B14: 1500
A15: Night use (8 hours) | B15: 1500
B17: Price | C17: Cost
A18: Flat Sheet | B18: 100 | C18: 50
A19: Pillows | B19: 50 | C19: 25
A20: Towels | B20: 50 | C20: 25
A21: Water | B21: 15 | C21: 8
A23: CLEANING FEE (during stay)
B24: Touch up | C24: Linens | D24: General Cleaning
A25: Studio | B25: 200 | C25: 200/set | D25: 350
A26: 1-bedroom | B26: 250 | C26: 200/set | D26: 400
A27: 2-bedroom | B27: 300 | C27: 200/set | D27: 600

Sheet BD Room Aquisitions
A1: UNIT TYPE | B1: DATE SIGNED | C1: STATUS | D1: TERMS | E1: OWNERS NAME | F1: CONTRACTS | G1: COMMISION RELEASED | H1: VOUCHER LINK
A2: OMP T3 10K | B2: 45778 | C2: LIVE | D2: 1 year | E2: Ibrahim Kabeer | F2: OMP T3 10K | G2: PENDING
A3: OMP T1 7U | B3: 45772 | C3: LIVE | D3: 6 months | E3: Milicent Tiu | F3: OMP T1 7U - NOTARY.pdf | G3: RELEASED
A4: SMDC BB 515 | B4: 45767 | C4: LIVE | D4: 6 months | E4: Ariel Sandoy | F4: SMDC BB 515 - NOTARY & S.P.A..pdf | G4: RELEASED
A5: WV T1 1013 | B5: 45767 | C5: LIVE | D5: 6 months | E5: Engr. Rijade Quezon | G5: PENDING
A6: WV T2 611 | B6: 45772 | C6: LIVE | D6: 6 months | E6: Sharmaine Cosculluella Cabial | F6: WV 2 6II.pdf | G6: PENDING
A7: AT T2 209 | B7: 45748 | C7: LIVE | D7: 6 months | E7: Katrina Samoro | G7: PENDING
A8: AT T1 501 | B8: 45753 | C8: LIVE | D8: 1 year | E8: Angelina Cordero | G8: PENDING
A9: SM 9 BC 208 | B9: 45753 | C9: LIVE | D9: 6 months | E9: Dan Mark Jurada | F9: SM 9 BC 208 - JURADA.pdf | G9: RELEASED
A10: SM 10 BA 1420 | B10: 45761 | C10: LIVE | D10: 6 months | E10: Sugar Ganancial | F10: SM 10 BA 1420 - GANANCIAL.pdf | G10: RELEASED
A11: SM 11 BA 624 | B11: 45761 | C11: LIVE | D11: 6 months | E11: Karen Go | F11: SM 11 BB 624 - GO.pdf | G11: RELEASED
A12: SH SW 8C | B12: 45790 | C12: LIVE | D12: 1 year | E12: Maricel Hoy | F12: SD SW 8C CONTRACT - HOY .pdf | G12: RELEASED
A13: TP NW 21B | B13: 45799 | C13: LIVE | D13: 1 year | E13: Amy Lapating | F13: TP NW 21B .pdf | G13: PENDING
A14: LPS 16S | B14: 45800 | C14: LIVE | D14: 1 year | E14: Christine Ladagohon | F14: LPS 16S | G14: PENDING
A15: WV 23 T1 508 | B15: 45799 | C15: PENDING | D15: 1 year | E15: Victor Raymundo Contreras | G15: PENDING
A16: WV 24 T1 511 | B16: 45799 | C16: PENDING | D16: 1 year | E16: Victor Raymundo Contreras | G16: PENDING
A17: WV 25 T1 512 | B17: 45799 | C17: PENDING | D17: 1 year | E17: Victor Raymundo Contreras | G17: PENDING
A18: WV 26 T1 513 | B18: 45799 | C18: PENDING | D18: 1 year | E18: Victor Raymundo Contreras | G18: PENDING
A19: WV 720 | B19: 45799 | C19: PENDING | D19: 1 year | E19: Victor Raymundo Contreras | G19: PENDING
A20: WV 616 | B20: 45799 | C20: PENDING | D20: 1 year | E20: Victor Raymundo Contreras | G20: PENDING
A21: SH NW 5T | B21: 45808 | C21: LIVE | D21: 1 year | E21: Mary Jean Talves Bearneza | F21: SH NW 5T - CONTRACT.pdf | G21: PENDING
A22: TP SW 8D | B22: 45817 | C22: LIVE | D22: 6 months | E22: JOAN REYES | G22: PENDING
A23: LPS 5E | B23: 45809 | C23: LIVE | D23: 1 year | E23: Mary Jean Talves Bearneza | F23: LPS 5E - CONTRACT (1).pdf | G23: PENDING
A24: AT T1 508 | B24: 45811 | C24: PENDING | D24: 1 year | E24: Cherry Pink Villa | G24: PENDING
A25: AT T4 117 | B25: 45811 | C25: LIVE | D25: 1 year | E25: Cherry Pink Villa | G25: PENDING
A26: WV T2 1013 | B26: 45816 | C26: LIVE | D26: 6 months | E26: Rijade Quezon | G26: PENDING
A27: WV T1 921 | B27: 45814 | C27: PENDING | D27: 1 year | E27: Shane Mercolita | G27: PENDING
A28: SMDC BC 117 | B28: 45821 | C28: PENDING | D28: 1 year | E28: Ces Jaranilla Villareal | G28: PENDING
A29: OMP T1 5B | B29: 45824 | C29: PENDING | D29: 1 year | E29: ROSS LIM | G29: PENDING
A30: OMP T2 9L | B30: 45824 | C30: LIVE | D30: 1 year | E30: ROSS LIM | G30: PENDING
A31: SD SW 8A | B31: 45828 | C31: PENDING | D31: 6 months | E31: ELLONAH SVET | G31: PENDING
A32: WV 1 918 | B32: 45828 | C32: PENDING | D32: 6 months | E32: Rose Vargas | G32: PENDING
